2023-08-24 08:56:25,982 - Debug Adapter (main) - CRITICAL - Debug adapter -> Extension: DEBUG_ADAPTER_STARTED
2023-08-24 08:56:25,985 - Debug Adapter (main) - CRITICAL - Debug adapter -> Extension: DEBUG_ADAPTER_READY2CONNECT
2023-08-24 08:56:33,524 - Debug Adapter (main) - WARNING - The operation took too long! - Measured 7.528712 s ( from ~ 08:56:25,995534)
2023-08-24 08:56:42,805 - Debug Adapter (main) - ERROR - unhashable type: 'dict'
Traceback (most recent call last):
  File "c:\Users\User\.vscode\extensions\espressif.esp-idf-extension-1.6.4\esp_debug_adapter\debug_adapter\command_processor.py", line 706, in on_setBreakpoints_request
    try_set_once(get_good_path(source.path), src_line, condition)
  File "c:\Users\User\.vscode\extensions\espressif.esp-idf-extension-1.6.4\esp_debug_adapter\debug_adapter\command_processor.py", line 677, in try_set_once
    raise e
  File "c:\Users\User\.vscode\extensions\espressif.esp-idf-extension-1.6.4\esp_debug_adapter\debug_adapter\command_processor.py", line 675, in try_set_once
    return self.da.source_break_add(source_path, line, condition=condition)
  File "c:\Users\User\.vscode\extensions\espressif.esp-idf-extension-1.6.4\esp_debug_adapter\debug_adapter\debug_adapter.py", line 523, in source_break_add
    bp_num = self._gdb.add_bp("{}:{}".format(src, line), ignore_count=0, cond=condition)
  File "C:\Users\User\.espressif\python_env\idf5.0_py3.8_env\lib\site-packages\esp_debug_backend\gdb.py", line 494, in add_bp
    raise DebuggerError('Failed to insert BP!')
esp_debug_backend.defs.DebuggerError: Failed to insert BP!

During handling of the above exception, another exception occurred:

Traceback (most recent call last):
  File "c:\Users\User\.vscode\extensions\espressif.esp-idf-extension-1.6.4\esp_debug_adapter\debug_adapter\command_processor.py", line 52, in __call__
    on_request(protocol_message)
  File "c:\Users\User\.vscode\extensions\espressif.esp-idf-extension-1.6.4\esp_debug_adapter\debug_adapter\command_processor.py", line 712, in on_setBreakpoints_request
    bp.update({{'message': e}})
TypeError: unhashable type: 'dict'
2023-08-24 08:56:51,353 - Debug Adapter (main) - WARNING - The step operation took too long - Measured 1.012587 s ( from ~ 08:56:50,340806)
2023-08-24 08:58:20,899 - Debug Adapter (main) - WARNING - The step operation took too long - Measured 1.008006 s ( from ~ 08:58:19,891155)
2023-08-24 09:59:39,114 - Debug Adapter (main) - CRITICAL - Debug adapter -> Extension: DEBUG_ADAPTER_STOPPED
